<?xml version="1.0" ?>
<!-- =================================================================================== -->
<!-- |    This document was autogenerated by xacro from src/AuboAMR300_ROS2/seer_description/urdf/composite_robot.urdf.xacro | -->
<!-- |    EDITING THIS FILE BY HAND IS NOT RECOMMENDED                                 | -->
<!-- =================================================================================== -->
<robot name="seer_aubo_composite">
  <link name="base_footprint">
    <inertial>
      <origin rpy="0 0 0" xyz="0 0 0"/>
      <mass value="0.0001"/>
      <inertia ixx="0.0001" ixy="0.0" ixz="0.0" iyy="0.0001" iyz="0.0" izz="0.0001"/>
    </inertial>
  </link>
  <joint name="base_joint" type="fixed">
    <parent link="base_footprint"/>
    <child link="base_link"/>
    <origin rpy="0 0 0" xyz="0.0 0.0 0.0"/>
  </joint>
  <link name="base_link">
    <visual>
      <origin rpy="0 0 3.141592653589793" xyz="0 0 0.26"/>
      <geometry>
        <mesh filename="package://seer_description/meshes/robot_body.stl" scale="0.1 0.1 0.1"/>
      </geometry>
      <material name="orange">
        <color rgba="0.922 0.57 0.82 1.0"/>
      </material>
    </visual>
    <collision>
      <origin rpy="0 0 0" xyz="0 0 0.35"/>
      <geometry>
        <box size="1.00 0.70 0.50"/>
      </geometry>
    </collision>
    <inertial>
      <origin rpy="0 0 0" xyz="0 0 0.15"/>
      <mass value="110.0"/>
      <inertia ixx="3.11" ixy="0.0" ixz="0.0" iyy="6.68" iyz="0.0" izz="8.15"/>
    </inertial>
  </link>
  <link name="left_wheel_link">
    <visual>
      <origin rpy="0 0 0" xyz="0 0 0"/>
      <geometry>
        <mesh filename="package://seer_description/meshes/left_wheel.stl" scale="0.1 0.1 0.1"/>
      </geometry>
      <material name="black">
        <color rgba="0.1 0.1 0.1 1.0"/>
      </material>
    </visual>
    <collision>
      <origin rpy="1.5707963267948966 0 0" xyz="0 0 0"/>
      <geometry>
        <cylinder length="0.05" radius="0.1"/>
      </geometry>
    </collision>
    <inertial>
      <origin rpy="1.5707963267948966 0 0" xyz="0 0 0"/>
      <mass value="6.0"/>
      <inertia ixx="0.01" ixy="0.0" ixz="0.0" iyy="0.01" iyz="0.0" izz="0.01"/>
    </inertial>
  </link>
  <joint name="left_wheel_joint" type="continuous">
    <parent link="base_link"/>
    <child link="left_wheel_link"/>
    <origin rpy="0 0 0" xyz="0.0 0.3 0.1"/>
    <axis xyz="0 1 0"/>
  </joint>
  <link name="right_wheel_link">
    <visual>
      <origin rpy="0 0 0" xyz="0 0 0"/>
      <geometry>
        <mesh filename="package://seer_description/meshes/right_wheel.stl" scale="0.1 0.1 0.1"/>
      </geometry>
      <material name="black">
        <color rgba="0.1 0.1 0.1 1.0"/>
      </material>
    </visual>
    <collision>
      <origin rpy="1.5707963267948966 0 0" xyz="0 0 0"/>
      <geometry>
        <cylinder length="0.05" radius="0.1"/>
      </geometry>
    </collision>
    <inertial>
      <origin rpy="1.5707963267948966 0 0" xyz="0 0 0"/>
      <mass value="6.0"/>
      <inertia ixx="0.01" ixy="0.0" ixz="0.0" iyy="0.01" iyz="0.0" izz="0.01"/>
    </inertial>
  </link>
  <joint name="right_wheel_joint" type="continuous">
    <parent link="base_link"/>
    <child link="right_wheel_link"/>
    <origin rpy="0 0 0" xyz="0.0 -0.3 0.1"/>
    <axis xyz="0 1 0"/>
  </joint>
  <link name="front_lidar_link">
    <visual>
      <origin rpy="0 0 0" xyz="0 0 0"/>
      <geometry>
        <mesh filename="package://seer_description/meshes/lidar.stl" scale="0.1 0.1 0.1"/>
      </geometry>
      <material name="grey">
        <color rgba="0.5 0.5 0.5 1.0"/>
      </material>
    </visual>
    <collision>
      <origin rpy="0 0 0" xyz="0 0 0"/>
      <geometry>
        <cylinder length="0.08" radius="0.05"/>
      </geometry>
    </collision>
    <inertial>
      <origin rpy="0 0 0" xyz="0 0 0"/>
      <mass value="0.3"/>
      <inertia ixx="0.01" ixy="0.0" ixz="0.0" iyy="0.01" iyz="0.0" izz="0.01"/>
    </inertial>
  </link>
  <joint name="front_lidar_joint" type="fixed">
    <parent link="base_link"/>
    <child link="front_lidar_link"/>
    <origin rpy="0 0 0" xyz="0.38 0.25 0.2"/>
  </joint>
  <link name="back_lidar_link">
    <visual>
      <origin rpy="0 0 0" xyz="0 0 0"/>
      <geometry>
        <mesh filename="package://seer_description/meshes/lidar.stl" scale="0.1 0.1 0.1"/>
      </geometry>
      <material name="grey">
        <color rgba="0.5 0.5 0.5 1.0"/>
      </material>
    </visual>
    <collision>
      <origin rpy="0 0 0" xyz="0 0 0"/>
      <geometry>
        <cylinder length="0.08" radius="0.05"/>
      </geometry>
    </collision>
    <inertial>
      <origin rpy="0 0 0" xyz="0 0 0"/>
      <mass value="0.3"/>
      <inertia ixx="0.01" ixy="0.0" ixz="0.0" iyy="0.01" iyz="0.0" izz="0.01"/>
    </inertial>
  </link>
  <joint name="back_lidar_joint" type="fixed">
    <parent link="base_link"/>
    <child link="back_lidar_link"/>
    <origin rpy="0 0 0" xyz="-0.38 -0.25 0.2"/>
  </joint>
  <link name="front_caster">
    <collision>
      <origin rpy="0 0 0" xyz="0 0 0"/>
      <geometry>
        <sphere radius="0.095"/>
      </geometry>
    </collision>
    <inertial>
      <mass value="1.0"/>
      <inertia ixx="0.01" ixy="0" ixz="0" iyy="0.01" iyz="0" izz="0.01"/>
    </inertial>
  </link>
  <link name="rear_caster">
    <collision>
      <origin rpy="0 0 0" xyz="0 0 0"/>
      <geometry>
        <sphere radius="0.095"/>
      </geometry>
    </collision>
    <inertial>
      <mass value="1.0"/>
      <inertia ixx="0.01" ixy="0" ixz="0" iyy="0.01" iyz="0" izz="0.01"/>
    </inertial>
  </link>
  <joint name="front_caster_joint" type="fixed">
    <parent link="base_link"/>
    <child link="front_caster"/>
    <origin rpy="0 0 0" xyz="0.3 0 0.095"/>
  </joint>
  <joint name="rear_caster_joint" type="fixed">
    <parent link="base_link"/>
    <child link="rear_caster"/>
    <origin rpy="0 0 0" xyz="-0.3 0 0.095"/>
  </joint>

  <dh_type type="modified"/>
  <safety_para singularity_consistent="0.02 0.01 10 0.2 0.045 10"/>
  <link name="aubo_base_link">
    <inertial>
      <origin rpy="0 0 0" xyz="0.000136 0.001601 0.018986"/>
      <mass value="2.592"/>
      <inertia ixx="0.008524" ixy="-0.000001" ixz="-0.000005" iyy="0.007934" iyz="-0.000081" izz="0.015304"/>
    </inertial>
    <visual>
      <origin rpy="0 0 0" xyz="0 0 0"/>
      <geometry>
        <!-- <mesh filename="package://seer_description/meshes/aubo_i16/visual/link0.DAE"/> -->
        <mesh filename="package://seer_description/meshes/aubo_i16/collision/link0.STL"/>
      </geometry>
      <material name="aubo_color">
        <color rgba="1 1 1 1"/>
      </material>
    </visual>
    <collision>
      <origin rpy="0 0 0" xyz="0 0 0"/>
      <geometry>
        <mesh filename="package://seer_description/meshes/aubo_i16/collision/link0.STL"/>
      </geometry>
    </collision>
  </link>
  <link name="shoulder_Link">
    <inertial>
      <origin rpy="0 0 0" xyz="-0.000004 0.005112 -0.026275"/>
      <mass value="10.180139"/>
      <inertia ixx="0.043326" ixy="0.000003" ixz="0.000003" iyy="0.042233" iyz="-0.001767" izz="0.029902"/>
    </inertial>
    <visual>
      <origin rpy="0 0 0" xyz="0 0 0"/>
      <geometry>
        <!-- <mesh filename="package://seer_description/meshes/aubo_i16/visual/link1.DAE"/> -->
        <mesh filename="package://seer_description/meshes/aubo_i16/collision/link1.STL"/>
      </geometry>
      <material name="aubo_color">
        <color rgba="0.89804 0.91765 0.92941 1"/>
      </material>
    </visual>
    <collision>
      <origin rpy="0 0 0" xyz="0 0 0"/>
      <geometry>
        <mesh filename="package://seer_description/meshes/aubo_i16/collision/link1.STL"/>
      </geometry>
    </collision>
  </link>
  <joint name="shoulder_joint" type="revolute">
    <origin rpy="0 0 3.1415926535897932384626433832795" xyz="0 0 0.163"/>
    <parent link="aubo_base_link"/>
    <child link="shoulder_Link"/>
    <axis xyz="0 0 1"/>
    <limit effort="267" lower="-6.283185307179586476925286766559" start_stop="411" upper="6.283185307179586476925286766559" velocity="3.1416"/>
    <property damping="0" inertia="4.9" motor_constant="8.75" offset="0" ratio="101" stiffness="0"/>
  </joint>
  <link name="upperArm_Link">
    <inertial>
      <origin rpy="0 0 0" xyz="0.170602 0.0000 -0.013024"/>
      <mass value="17.66406"/>
      <inertia ixx="0.063521" ixy="0.00002" ixz="-0.024888" iyy="0.847528" iyz="0.000005" izz="0.828847"/>
    </inertial>
    <visual>
      <origin rpy="0 0 0" xyz="0 0 0"/>
      <geometry>
        <!-- <mesh filename="package://seer_description/meshes/aubo_i16/visual/link2.DAE"/> -->
        <mesh filename="package://seer_description/meshes/aubo_i16/collision/link2.STL"/>
      </geometry>
      <material name="aubo_color">
        <color rgba="0.89804 0.91765 0.92941 1"/>
      </material>
    </visual>
    <collision>
      <origin rpy="0 0 0" xyz="0 0 0"/>
      <geometry>
        <mesh filename="package://seer_description/meshes/aubo_i16/collision/link2.STL"/>
      </geometry>
    </collision>
  </link>
  <joint name="upperArm_joint" type="revolute">
    <origin rpy="-1.5707963267948966192313216916398 -1.5707963267948966192313216916398 0" xyz="0 0.191 0"/>
    <parent link="shoulder_Link"/>
    <child link="upperArm_Link"/>
    <axis xyz="0 0 1"/>
    <limit effort="267" lower="-6.283185307179586476925286766559" start_stop="411" upper="6.283185307179586476925286766559" velocity="3.1416"/>
    <property damping="0" inertia="4.9" motor_constant="8.75" offset="0" ratio="101" stiffness="0"/>
  </joint>
  <link name="foreArm_Link">
    <inertial>
      <origin rpy="0 0 0" xyz="0.269208 -0.000022 0.106467"/>
      <mass value="3.926354"/>
      <inertia ixx="0.006007" ixy="0.000009" ixz="0.001991" iyy="0.08378" iyz="0.000005" izz="0.082433"/>
    </inertial>
    <visual>
      <origin rpy="0 0 0" xyz="0 0 0"/>
      <geometry>
        <!-- <mesh filename="package://seer_description/meshes/aubo_i16/visual/link3.DAE"/> -->
        <mesh filename="package://seer_description/meshes/aubo_i16/collision/link3.STL"/>
      </geometry>
      <material name="aubo_color">
        <color rgba="1 1 1 1"/>
      </material>
    </visual>
    <collision>
      <origin rpy="0 0 0" xyz="0 0 0"/>
      <geometry>
        <mesh filename="package://seer_description/meshes/aubo_i16/collision/link3.STL"/>
      </geometry>
    </collision>
  </link>
  <joint name="foreArm_joint" type="revolute">
    <origin rpy="-3.1415926535897932384626433832795 0 0" xyz="0.480 0 0"/>
    <parent link="upperArm_Link"/>
    <child link="foreArm_Link"/>
    <axis xyz="0 0 1"/>
    <limit effort="133" lower="-6.283185307179586476925286766559" start_stop="207" upper="6.283185307179586476925286766559" velocity="4.6600"/>
    <property damping="0" inertia="2.0" motor_constant="8.72" offset="0" ratio="101" stiffness="0"/>
  </joint>
  <link name="wrist1_Link">
    <inertial>
      <origin rpy="0 0 0" xyz="0.000036 0.01561 -0.001526"/>
      <mass value="2.370741"/>
      <inertia ixx="0.003672" ixy="0.000006" ixz="-0.000001" iyy="0.00219" iyz="-0.00008" izz="0.003621"/>
    </inertial>
    <visual>
      <origin rpy="0 0 0" xyz="0 0 0"/>
      <geometry>
        <!-- <mesh filename="package://seer_description/meshes/aubo_i16/visual/link4.DAE"/> -->
        <mesh filename="package://seer_description/meshes/aubo_i16/collision/link4.STL"/>
      </geometry>
      <material name="aubo_color">
        <color rgba="1 1 1 1"/>
      </material>
    </visual>
    <collision>
      <origin rpy="0 0 0" xyz="0 0 0"/>
      <geometry>
        <mesh filename="package://seer_description/meshes/aubo_i16/collision/link4.STL"/>
      </geometry>
    </collision>
  </link>
  <joint name="wrist1_joint" type="revolute">
    <origin rpy="3.1415926535897932384626433832795 0 1.5707963267948966192313216916398" xyz="0.370 0 0"/>
    <parent link="foreArm_Link"/>
    <child link="wrist1_Link"/>
    <axis xyz="0 0 1"/>
    <limit effort="49" lower="-6.283185307179586476925286766559" start_stop="66" upper="6.283185307179586476925286766559" velocity="3.1416"/>
    <property damping="0" inertia="0" motor_constant="8.81" offset="0" ratio="101" stiffness="0"/>
  </joint>
  <link name="wrist2_Link">
    <inertial>
      <origin rpy="0 0 0" xyz="-0.000036 -0.01561 -0.001526"/>
      <mass value="2.370741"/>
      <inertia ixx="0.003672" ixy="0.000006" ixz="0.000001" iyy="0.00219" iyz="0.00008" izz="0.003621"/>
    </inertial>
    <visual>
      <origin rpy="0 0 0" xyz="0 0 0"/>
      <geometry>
        <!-- <mesh filename="package://seer_description/meshes/aubo_i16/visual/link5.DAE"/> -->
        <mesh filename="package://seer_description/meshes/aubo_i16/collision/link5.STL"/>
      </geometry>
      <material name="aubo_color">
        <color rgba="1 1 1 1"/>
      </material>
    </visual>
    <collision>
      <origin rpy="0 0 0" xyz="0 0 0"/>
      <geometry>
        <mesh filename="package://seer_description/meshes/aubo_i16/collision/link5.STL"/>
      </geometry>
    </collision>
  </link>
  <joint name="wrist2_joint" type="revolute">
    <origin rpy="-1.5707963267948966192313216916398 0 0" xyz="0 0.1175 0"/>
    <parent link="wrist1_Link"/>
    <child link="wrist2_Link"/>
    <axis xyz="0 0 1"/>
    <limit effort="49" lower="-6.283185307179586476925286766559" start_stop="66" upper="6.283185307179586476925286766559" velocity="3.1416"/>
    <property damping="0" inertia="0" motor_constant="8.814" offset="0" ratio="101" stiffness="0"/>
  </joint>
  <link name="wrist3_Link">
    <inertial>
      <origin rpy="0 0 0" xyz="0.000508 0.000344 -0.017049"/>
      <mass value="0.259654"/>
      <inertia ixx="0.000162" ixy="0.0000" ixz="0.0000" iyy="0.000162" iyz="0.000001" izz="0.000273"/>
    </inertial>
    <visual>
      <origin rpy="0 0 0" xyz="0 0 0"/>
      <geometry>
        <!-- <mesh filename="package://seer_description/meshes/aubo_i16/visual/link6.DAE"/> -->
        <mesh filename="package://seer_description/meshes/aubo_i16/collision/link6.STL"/>
      </geometry>
      <material name="aubo_color">
        <color rgba="1 1 1 1"/>
      </material>
    </visual>
    <collision>
      <origin rpy="0 0 0" xyz="0 0 0"/>
      <geometry>
        <mesh filename="package://seer_description/meshes/aubo_i16/collision/link6.STL"/>
      </geometry>
    </collision>
  </link>
  <joint name="wrist3_joint" type="revolute">
    <origin rpy="1.5707963267948966192313216916398 0 0" xyz="0 -0.1035 0"/>
    <parent link="wrist2_Link"/>
    <child link="wrist3_Link"/>
    <axis xyz="0 0 1"/>
    <limit effort="49" lower="-6.283185307179586476925286766559" start_stop="66" upper="6.283185307179586476925286766559" velocity="3.1416"/>
    <property damping="0" inertia="0" motor_constant="8.814" offset="0" ratio="101" stiffness="0"/>
  </joint>
  <joint name="arm_mount_joint" type="fixed">
    <parent link="base_link"/>
    <child link="aubo_base_link"/>
    <origin rpy="0 0 3.141592653589793" xyz="-0.3 0.0 0.6"/>
  </joint>
  <ros2_control name="GazeboSimSystem" type="system">
    <hardware>
      <plugin>gz_ros2_control/GazeboSimSystem</plugin>
    </hardware>
    <joint name="shoulder_joint">
      <command_interface name="position">
        <param name="min">-6.28</param>
        <param name="max">6.28</param>
      </command_interface>
      <state_interface name="position"/>
      <state_interface name="velocity"/>
      <state_interface name="effort"/>
    </joint>
    <joint name="upperArm_joint">
      <command_interface name="position">
        <param name="min">-6.28</param>
        <param name="max">6.28</param>
      </command_interface>
      <state_interface name="position"/>
      <state_interface name="velocity"/>
      <state_interface name="effort"/>
    </joint>
    <joint name="foreArm_joint">
      <command_interface name="position">
        <param name="min">-6.28</param>
        <param name="max">6.28</param>
      </command_interface>
      <state_interface name="position"/>
      <state_interface name="velocity"/>
      <state_interface name="effort"/>
    </joint>
    <joint name="wrist1_joint">
      <command_interface name="position">
        <param name="min">-6.28</param>
        <param name="max">6.28</param>
      </command_interface>
      <state_interface name="position"/>
      <state_interface name="velocity"/>
      <state_interface name="effort"/>
    </joint>
    <joint name="wrist2_joint">
      <command_interface name="position">
        <param name="min">-6.28</param>
        <param name="max">6.28</param>
      </command_interface>
      <state_interface name="position"/>
      <state_interface name="velocity"/>
      <state_interface name="effort"/>
    </joint>
    <joint name="wrist3_joint">
      <command_interface name="position">
        <param name="min">-6.28</param>
        <param name="max">6.28</param>
      </command_interface>
      <state_interface name="position"/>
      <state_interface name="velocity"/>
      <state_interface name="effort"/>
    </joint>
  </ros2_control>

  <link name="camera_link">
    <inertial>
      <origin rpy="0 0 0" xyz="0.00287577972418718 0.000617475958990782 0.0141094270811986"/>
      <mass value="0.0330710167577971"/>
      <inertia ixx="4.44764516625696E-05" ixy="5.53948591538607E-08" ixz="-2.79060738018455E-08" iyy="3.07720636867613E-06" iyz="1.65209163393457E-07" izz="4.23385079682874E-05"/>
    </inertial>
    <visual>
      <origin rpy="0 0 0" xyz="-0.011715 -0.0475 -0.014311"/>
      <geometry>
        <mesh filename="package://seer_description/meshes/gemini335L_336L/base_link.STL"/>
      </geometry>
      <material name="gemini_color">
        <color rgba="0.792156862745098 0.819607843137255 0.933333333333333 1"/>
      </material>
    </visual>
    <collision>
      <origin rpy="0 0 0" xyz="0 0 0"/>
      <geometry>
        <mesh filename="package://seer_description/meshes/gemini335L_336L/base_link.STL"/>
      </geometry>
    </collision>
  </link>
  <link name="camera_color_screw_frame">
    <inertial>
      <origin rpy="0 0 0" xyz="-0.000565327084882765 -0.000754794567604389 0.0132965378040367"/>
      <mass value="0.00682237197281727"/>
      <inertia ixx="6.29665283187838E-06" ixy="-5.56290557545124E-09" ixz="-4.00728156039594E-09" iyy="3.51296306719609E-07" iyz="1.01025992411894E-07" izz="5.98951376451163E-06"/>
    </inertial>
    <visual>
      <origin rpy="0 0 0" xyz="0 0 0"/>
      <geometry>
        <mesh filename="package://seer_description/meshes/gemini335L_336L/camera_color_screw_frame.STL"/>
      </geometry>
      <material name="gemini_color">
        <color rgba="0.792156862745098 0.819607843137255 0.933333333333333 1"/>
      </material>
    </visual>
    <collision>
      <origin rpy="0 0 0" xyz="0 0 0"/>
      <geometry>
        <mesh filename="package://seer_description/meshes/gemini335L_336L/camera_color_screw_frame.STL"/>
      </geometry>
    </collision>
  </link>
  <joint name="camera_color_screw_joint" type="fixed">
    <origin rpy="0 0 0" xyz="-0.011715 -0.0475 -0.014311"/>
    <parent link="camera_link"/>
    <child link="camera_color_screw_frame"/>
    <axis xyz="0 0 0"/>
  </joint>
  <link name="camera_IMU_frame">
    <inertial>
      <origin rpy="0 0 0" xyz="-0.000484999999999999 0 0"/>
      <mass value="1.1218632E-05"/>
      <inertia ixx="2.18587565431999E-11" ixy="0" ixz="-3.24383195391647E-28" iyy="1.0215031879E-11" iyz="-3.36058814408671E-29" izz="1.34029931389999E-11"/>
    </inertial>
    <visual>
      <origin rpy="0 0 0" xyz="0 0 0"/>
      <geometry>
        <mesh filename="package://seer_description/meshes/gemini335L_336L/camera_IMU_frame.STL"/>
      </geometry>
      <material name="gemini_color">
        <color rgba="0.792156862745098 0.819607843137255 0.933333333333333 1"/>
      </material>
    </visual>
    <collision>
      <origin rpy="0 0 0" xyz="0 0 0"/>
      <geometry>
        <mesh filename="package://seer_description/meshes/gemini335L_336L/camera_IMU_frame.STL"/>
      </geometry>
    </collision>
  </link>
  <joint name="camera_IMU_joint" type="fixed">
    <origin rpy="0 0 0" xyz="-0.01425 -0.007866 -0.001068"/>
    <parent link="camera_depth_frame"/>
    <child link="camera_IMU_frame"/>
    <axis xyz="0 0 0"/>
  </joint>
  <link name="camera_depth_frame">
    <inertial>
      <origin rpy="0 0 0" xyz="-0.00158020638644197 -1.72113892998871E-08 -1.52265896501485E-07"/>
      <mass value="0.00045316775745635"/>
      <inertia ixx="4.34107394943177E-09" ixy="-3.70457372455813E-13" ixz="-1.46474854133768E-13" iyy="4.84011101176503E-09" iyz="2.21976196909378E-14" izz="4.84043649602512E-09"/>
    </inertial>
    <visual>
      <origin rpy="0 0 0" xyz="0 0 0"/>
      <geometry>
        <mesh filename="package://seer_description/meshes/gemini335L_336L/camera_depth_frame.STL"/>
      </geometry>
      <material name="gemini_color">
        <color rgba="0.792156862745098 0.819607843137255 0.933333333333333 1"/>
      </material>
    </visual>
    <collision>
      <origin rpy="0 0 0" xyz="0 0 0"/>
      <geometry>
        <mesh filename="package://seer_description/meshes/gemini335L_336L/camera_depth_frame.STL"/>
      </geometry>
    </collision>
  </link>
  <joint name="camera_depth_joint" type="fixed">
    <origin rpy="0 0 0" xyz="0 0 0"/>
    <parent link="camera_link"/>
    <child link="camera_depth_frame"/>
    <axis xyz="0 0 0"/>
  </joint>
  <link name="camera_left_ir_frame">
    <inertial>
      <origin rpy="0 0 0" xyz="-0.00158020638644197 -1.72113892998871E-08 -1.52265896501463E-07"/>
      <mass value="0.00045316775745635"/>
      <inertia ixx="4.34107394943177E-09" ixy="-3.70457372455807E-13" ixz="-1.464748541338E-13" iyy="4.84011101176503E-09" iyz="2.21976196909559E-14" izz="4.84043649602512E-09"/>
    </inertial>
    <visual>
      <origin rpy="0 0 0" xyz="0 0 0"/>
      <geometry>
        <mesh filename="package://seer_description/meshes/gemini335L_336L/camera_infra1_frame.STL"/>
      </geometry>
      <material name="gemini_color">
        <color rgba="0.792156862745098 0.819607843137255 0.933333333333333 1"/>
      </material>
    </visual>
    <collision>
      <origin rpy="0 0 0" xyz="0 0 0"/>
      <geometry>
        <mesh filename="package://seer_description/meshes/gemini335L_336L/camera_infra1_frame.STL"/>
      </geometry>
    </collision>
  </link>
  <joint name="camera_left_ir_joint" type="fixed">
    <origin rpy="0 0 0" xyz="0 0 0"/>
    <parent link="camera_depth_frame"/>
    <child link="camera_left_ir_frame"/>
    <axis xyz="0 0 0"/>
  </joint>
  <link name="camera_left_ir_optical_frame">
    <inertial>
      <origin rpy="0 0 0" xyz="1.72113892998871E-08 1.52265896501462E-07 -0.00158020638644197"/>
      <mass value="0.00045316775745635"/>
      <inertia ixx="4.84011101176503E-09" ixy="2.2197619690945E-14" ixz="3.70457372455806E-13" iyy="4.84043649602512E-09" iyz="1.46474854133777E-13" izz="4.34107394943177E-09"/>
    </inertial>
    <visual>
      <origin rpy="0 0 0" xyz="0 0 0"/>
      <geometry>
        <mesh filename="package://seer_description/meshes/gemini335L_336L/camera_infra1_optical_frame.STL"/>
      </geometry>
      <material name="gemini_color">
        <color rgba="0.792156862745098 0.819607843137255 0.933333333333333 1"/>
      </material>
    </visual>
    <collision>
      <origin rpy="0 0 0" xyz="0 0 0"/>
      <geometry>
        <mesh filename="package://seer_description/meshes/gemini335L_336L/camera_infra1_optical_frame.STL"/>
      </geometry>
    </collision>
  </link>
  <joint name="camera_left_ir_optical_joint" type="fixed">
    <origin rpy="-1.5708 0 -1.5708" xyz="0 0 0"/>
    <parent link="camera_left_ir_frame"/>
    <child link="camera_left_ir_optical_frame"/>
    <axis xyz="0 0 0"/>
  </joint>
  <link name="camera_right_ir_frame">
    <inertial>
      <origin rpy="0 0 0" xyz="-0.00158020638644197 -1.72113892998871E-08 -1.5226589649853E-07"/>
      <mass value="0.000453167757456349"/>
      <inertia ixx="4.34107394943177E-09" ixy="-3.70457372454514E-13" ixz="-1.46474854139355E-13" iyy="4.84011101176503E-09" iyz="2.21976196892825E-14" izz="4.84043649602512E-09"/>
    </inertial>
    <visual>
      <origin rpy="0 0 0" xyz="0 0 0"/>
      <geometry>
        <mesh filename="package://seer_description/meshes/gemini335L_336L/camera_infra2_frame.STL"/>
      </geometry>
      <material name="gemini_color">
        <color rgba="0.792156862745098 0.819607843137255 0.933333333333333 1"/>
      </material>
    </visual>
    <collision>
      <origin rpy="0 0 0" xyz="0 0 0"/>
      <geometry>
        <mesh filename="package://seer_description/meshes/gemini335L_336L/camera_infra2_frame.STL"/>
      </geometry>
    </collision>
  </link>
  <joint name="camera_right_ir_joint" type="fixed">
    <origin rpy="0 0 0" xyz="0 -0.095 0"/>
    <parent link="camera_depth_frame"/>
    <child link="camera_right_ir_frame"/>
    <axis xyz="0 0 0"/>
  </joint>
  <link name="camera_right_ir_optical_frame">
    <inertial>
      <origin rpy="0 0 0" xyz="1.72113892998871E-08 1.52265896498545E-07 -0.00158020638644197"/>
      <mass value="0.000453167757456349"/>
      <inertia ixx="4.84011101176503E-09" ixy="2.21976196892926E-14" ixz="3.7045737245453E-13" iyy="4.84043649602512E-09" iyz="1.46474854139357E-13" izz="4.34107394943177E-09"/>
    </inertial>
    <visual>
      <origin rpy="0 0 0" xyz="0 0 0"/>
      <geometry>
        <mesh filename="package://seer_description/meshes/gemini335L_336L/camera_infra2_optical_frame.STL"/>
      </geometry>
      <material name="gemini_color">
        <color rgba="0.792156862745098 0.819607843137255 0.933333333333333 1"/>
      </material>
    </visual>
    <collision>
      <origin rpy="0 0 0" xyz="0 0 0"/>
      <geometry>
        <mesh filename="package://seer_description/meshes/gemini335L_336L/camera_infra2_optical_frame.STL"/>
      </geometry>
    </collision>
  </link>
  <joint name="camera_right_ir_optical_joint" type="fixed">
    <origin rpy="-1.5708 0 -1.5708" xyz="0 0 0"/>
    <parent link="camera_right_ir_frame"/>
    <child link="camera_right_ir_optical_frame"/>
    <axis xyz="0 0 0"/>
  </joint>
  <link name="camera_color_frame">
    <inertial>
      <origin rpy="0 0 0" xyz="-0.00158020000774522 -2.03380748700632E-08 -1.59580992343651E-07"/>
      <mass value="0.000453166139060244"/>
      <inertia ixx="4.34106103694197E-09" ixy="-3.74713926702605E-13" ixz="-1.54192867143563E-13" iyy="4.84009702890227E-09" iyz="1.94453950166097E-14" izz="4.8404288092859E-09"/>
    </inertial>
    <visual>
      <origin rpy="0 0 0" xyz="0 0 0"/>
      <geometry>
        <mesh filename="package://seer_description/meshes/gemini335L_336L/camera_color_frame.STL"/>
      </geometry>
      <material name="gemini_color">
        <color rgba="0.501960784313725 0.250980392156863 0.250980392156863 1"/>
      </material>
    </visual>
    <collision>
      <origin rpy="0 0 0" xyz="0 0 0"/>
      <geometry>
        <mesh filename="package://seer_description/meshes/gemini335L_336L/camera_color_frame.STL"/>
      </geometry>
    </collision>
  </link>
  <joint name="camera_color_joint" type="fixed">
    <origin rpy="0.0010157 0 0" xyz="0 -0.02375 0"/>
    <parent link="camera_depth_frame"/>
    <child link="camera_color_frame"/>
    <axis xyz="0 0 0"/>
  </joint>
  <link name="camera_color_optical_frame">
    <inertial>
      <origin rpy="0 0 0" xyz="2.03380748735327E-08 1.59580992343634E-07 -0.00158020000774522"/>
      <mass value="0.000453166139060244"/>
      <inertia ixx="4.84009702890227E-09" ixy="1.94453950166198E-14" ixz="3.74713926702576E-13" iyy="4.8404288092859E-09" iyz="1.5419286714356E-13" izz="4.34106103694197E-09"/>
    </inertial>
    <visual>
      <origin rpy="0 0 0" xyz="0 0 0"/>
      <geometry>
        <mesh filename="package://seer_description/meshes/gemini335L_336L/camera_color_optical_frame.STL"/>
      </geometry>
      <material name="gemini_color">
        <color rgba="0.501960784313725 0.250980392156863 0.250980392156863 1"/>
      </material>
    </visual>
    <collision>
      <origin rpy="0 0 0" xyz="0 0 0"/>
      <geometry>
        <mesh filename="package://seer_description/meshes/gemini335L_336L/camera_color_optical_frame.STL"/>
      </geometry>
    </collision>
  </link>
  <joint name="camera_color_optical_joint" type="fixed">
    <origin rpy="-1.5708 0 -1.5708" xyz="0 0 0"/>
    <parent link="camera_color_frame"/>
    <child link="camera_color_optical_frame"/>
    <axis xyz="0 0 0"/>
  </joint>

  <joint name="camera_joint" type="fixed">
    <parent link="wrist3_Link"/>
    <child link="camera_link"/>
    <origin rpy="1.5707963267948966 -1.5707963267948966 3.141592653589793" xyz="0.00 0.08 0.00"/>
  </joint>
</robot>
