<?xml version="1.0"?>
<robot name="seer_amb" xmlns:xacro="http://ros.org/wiki/xacro">

  <xacro:property name="base_mass" value="110.0" />
  <xacro:property name="wheel_mass" value="6.0" />

  <xacro:property name="wheel_radius" value="0.1" />
  <xacro:property name="wheel_length" value="0.05" />

  <xacro:property name="wheel_ygap" value="0.3" />
  <xacro:property name="wheel_xoff" value="0.0" />
  <xacro:property name="wheel_zoff" value="0.05" />

  <link name="base_footprint" />

  <joint name="base_joint" type="fixed">
    <parent link="base_footprint" />
    <child link="base_link" />
    <origin xyz="0.0 0.0 ${wheel_radius - wheel_zoff}" rpy="0 0 0" />
  </joint>

  <link name="base_link">
    <visual>
      <origin xyz="0 0 0.2" rpy="0 0 0" />
      <geometry>
        <mesh filename="package://seer_description/meshes/robot_body.stl" scale="0.1 0.1 0.1" />
      </geometry>
      <material name="white">
        <color rgba="0.9 0.9 0.9 1.0" />
      </material>
    </visual>

    <collision>
      <origin xyz="0 0 0.15" rpy="0 0 0" />
      <geometry>
        <box size="0.8 0.5 0.3" />
      </geometry>
    </collision>

    <inertial>
      <origin xyz="0 0 0.15" rpy="0 0 0" />
      <mass value="${base_mass}" />
      <inertia ixx="1.0" ixy="0.0" ixz="0.0" iyy="1.0" iyz="0.0" izz="1.0" />
    </inertial>
  </link>

  <xacro:macro name="drive_wheel" params="prefix y_reflect filename">
    <link name="${prefix}_wheel_link">
      <visual>
        <origin xyz="0 0 0" rpy="0 0 0" />
        <geometry>
          <mesh filename="package://seer_description/meshes/${filename}" scale="0.1 0.1 0.1" />
        </geometry>
        <material name="black">
          <color rgba="0.1 0.1 0.1 1.0" />
        </material>
      </visual>

      <collision>
        <origin xyz="0 0 0" rpy="${pi/2} 0 0" />
        <geometry>
          <cylinder radius="${wheel_radius}" length="${wheel_length}" />
        </geometry>
      </collision>

      <inertial>
        <origin xyz="0 0 0" rpy="${pi/2} 0 0" />
        <mass value="${wheel_mass}" />
        <inertia ixx="0.01" ixy="0.0" ixz="0.0" iyy="0.01" iyz="0.0" izz="0.01" />
      </inertial>
    </link>

    <joint name="${prefix}_wheel_joint" type="continuous">
      <parent link="base_link" />
      <child link="${prefix}_wheel_link" />
      <origin xyz="${wheel_xoff} ${y_reflect * wheel_ygap} ${wheel_zoff}" rpy="0 0 0" />
      <axis xyz="0 1 0" />
    </joint>
  </xacro:macro>

  <xacro:drive_wheel prefix="left" y_reflect="1" filename="left_wheel.stl" />
  <xacro:drive_wheel prefix="right" y_reflect="-1" filename="right_wheel.stl" />

  <link name="front_caster">
    <collision>
      <origin xyz="0 0 0" rpy="0 0 0" />
      <geometry>
        <sphere radius="${wheel_radius - 0.005}" />
      </geometry>
    </collision>
    <inertial>
      <mass value="1.0" />
      <inertia ixx="0.01" ixy="0" ixz="0" iyy="0.01" iyz="0" izz="0.01" />
    </inertial>
  </link>

  <joint name="front_caster_joint" type="fixed">
    <parent link="base_link" />
    <child link="front_caster" />
    <origin xyz="0.3 0 ${wheel_zoff}" rpy="0 0 0" />
  </joint>

  <link name="rear_caster">
    <collision>
      <origin xyz="0 0 0" rpy="0 0 0" />
      <geometry>
        <sphere radius="${wheel_radius - 0.005}" />
      </geometry>
    </collision>
    <inertial>
      <mass value="1.0" />
      <inertia ixx="0.01" ixy="0" ixz="0" iyy="0.01" iyz="0" izz="0.01" />
    </inertial>
  </link>

  <joint name="rear_caster_joint" type="fixed">
    <parent link="base_link" />
    <child link="rear_caster" />
    <origin xyz="-0.3 0 ${wheel_zoff}" rpy="0 0 0" />
  </joint>

  <!-- control simulation gazebo -->

  <gazebo reference="base_link">
    <material>Gazebo/White</material>
  </gazebo>

  <gazebo reference="left_wheel_link">
    <material>Gazebo/Black</material>
    <mu1>1.0</mu1>
    <mu2>1.0</mu2>
  </gazebo>

  <gazebo reference="right_wheel_link">
    <material>Gazebo/Black</material>
    <mu1>1.0</mu1>
    <mu2>1.0</mu2>
  </gazebo>

  <gazebo reference="front_caster">
    <mu1>0.0</mu1>
    <mu2>0.0</mu2>
    <material>Gazebo/Grey</material>
  </gazebo>

  <gazebo reference="rear_caster">
    <mu1>0.0</mu1>
    <mu2>0.0</mu2>
    <material>Gazebo/Grey</material>
  </gazebo>
  <gazebo>
    <plugin filename="gz-sim-diff-drive-system" name="gz::sim::systems::DiffDrive">
      <left_joint>left_wheel_joint</left_joint>
      <right_joint>right_wheel_joint</right_joint>

      <wheel_separation>${wheel_ygap * 2}</wheel_separation>
      <wheel_radius>${wheel_radius}</wheel_radius>
      <max_linear_acceleration>1.0</max_linear_acceleration>
      <max_angular_acceleration>2.0</max_angular_acceleration>
      <max_linear_velocity>1.5</max_linear_velocity>
      <max_angular_velocity>2.0</max_angular_velocity>

      <topic>cmd_vel</topic>
      <odom_topic>odom</odom_topic>
      <frame_id>odom</frame_id>
      <child_frame_id>base_footprint</child_frame_id>
      <odom_publisher_frequency>30</odom_publisher_frequency>
    </plugin>

    <plugin filename="gz-sim-joint-state-publisher-system"
      name="gz::sim::systems::JointStatePublisher">
      <topic>joint_states</topic>
      <joint_name>left_wheel_joint</joint_name>
      <joint_name>right_wheel_joint</joint_name>
    </plugin>
  </gazebo>
  <!-- <gazebo>
    <plugin name="gazebo_ros_diff_drive" filename="libgazebo_ros_diff_drive.so">
      <ros>
        <namespace>/</namespace>
        <remapping>cmd_vel:=cmd_vel</remapping>
        <remapping>odom:=odom</remapping>
      </ros>

      <left_joint>left_wheel_joint</left_joint>
      <right_joint>right_wheel_joint</right_joint>

      <wheel_separation>${wheel_ygap * 2}</wheel_separation>
      <wheel_diameter>${wheel_radius * 2}</wheel_diameter>

      <max_wheel_torque>200</max_wheel_torque>
      <max_wheel_acceleration>10.0</max_wheel_acceleration>

      <publish_odom>true</publish_odom>
      <publish_odom_tf>true</publish_odom_tf>
      <publish_wheel_tf>true</publish_wheel_tf>

      <odometry_frame>odom</odometry_frame>
      <robot_base_frame>base_footprint</robot_base_frame>
    </plugin>
  </gazebo> -->
</robot>