<?xml version="1.0" ?>
<!-- =================================================================================== -->
<!-- |    This document was autogenerated by xacro from src/AuboAMR300_ROS2/seer_description/urdf/seer_robot_base.urdf.xacro | -->
<!-- |    EDITING THIS FILE BY HAND IS NOT RECOMMENDED                                 | -->
<!-- =================================================================================== -->
<robot name="seer_amb">
  <link name="base_footprint"/>
  <joint name="base_joint" type="fixed">
    <parent link="base_footprint"/>
    <child link="base_link"/>
    <origin rpy="0 0 0" xyz="0.0 0.0 0.0"/>
  </joint>
  <link name="base_link">
    <visual>
      <origin rpy="0 0 3.141592653589793" xyz="0 0 0.26"/>
      <geometry>
        <mesh filename="package://seer_description/meshes/robot_body.stl" scale="0.1 0.1 0.1"/>
      </geometry>
      <material name="orange">
        <color rgba="0.922 0.57 0.82 1.0"/>
      </material>
    </visual>
    <collision>
      <origin rpy="0 0 0" xyz="0 0 0.2"/>
      <geometry>
        <box size="0.8 0.5 0.3"/>
      </geometry>
    </collision>
    <inertial>
      <origin rpy="0 0 0" xyz="0 0 0.15"/>
      <mass value="110.0"/>
      <inertia ixx="3.11" ixy="0.0" ixz="0.0" iyy="6.68" iyz="0.0" izz="8.15"/>
    </inertial>
  </link>
  <link name="left_wheel_link">
    <visual>
      <origin rpy="0 0 0" xyz="0 0 0"/>
      <geometry>
        <mesh filename="package://seer_description/meshes/left_wheel.stl" scale="0.1 0.1 0.1"/>
      </geometry>
      <material name="black">
        <color rgba="0.1 0.1 0.1 1.0"/>
      </material>
    </visual>
    <collision>
      <origin rpy="1.5707963267948966 0 0" xyz="0 0 0"/>
      <geometry>
        <cylinder length="0.05" radius="0.1"/>
      </geometry>
    </collision>
    <inertial>
      <origin rpy="1.5707963267948966 0 0" xyz="0 0 0"/>
      <mass value="6.0"/>
      <inertia ixx="0.01" ixy="0.0" ixz="0.0" iyy="0.01" iyz="0.0" izz="0.01"/>
    </inertial>
  </link>
  <joint name="left_wheel_joint" type="continuous">
    <parent link="base_link"/>
    <child link="left_wheel_link"/>
    <origin rpy="0 0 0" xyz="0.0 0.3 0.1"/>
    <axis xyz="0 1 0"/>
  </joint>
  <link name="right_wheel_link">
    <visual>
      <origin rpy="0 0 0" xyz="0 0 0"/>
      <geometry>
        <mesh filename="package://seer_description/meshes/right_wheel.stl" scale="0.1 0.1 0.1"/>
      </geometry>
      <material name="black">
        <color rgba="0.1 0.1 0.1 1.0"/>
      </material>
    </visual>
    <collision>
      <origin rpy="1.5707963267948966 0 0" xyz="0 0 0"/>
      <geometry>
        <cylinder length="0.05" radius="0.1"/>
      </geometry>
    </collision>
    <inertial>
      <origin rpy="1.5707963267948966 0 0" xyz="0 0 0"/>
      <mass value="6.0"/>
      <inertia ixx="0.01" ixy="0.0" ixz="0.0" iyy="0.01" iyz="0.0" izz="0.01"/>
    </inertial>
  </link>
  <joint name="right_wheel_joint" type="continuous">
    <parent link="base_link"/>
    <child link="right_wheel_link"/>
    <origin rpy="0 0 0" xyz="0.0 -0.3 0.1"/>
    <axis xyz="0 1 0"/>
  </joint>
  <link name="front_lidar_link">
    <visual>
      <origin rpy="0 0 0" xyz="0 0 0"/>
      <geometry>
        <mesh filename="package://seer_description/meshes/lidar.stl" scale="0.1 0.1 0.1"/>
      </geometry>
      <material name="grey">
        <color rgba="0.5 0.5 0.5 1.0"/>
      </material>
    </visual>
    <collision>
      <origin rpy="0 0 0" xyz="0 0 0"/>
      <geometry>
        <cylinder length="0.08" radius="0.05"/>
      </geometry>
    </collision>
    <inertial>
      <origin rpy="0 0 0" xyz="0 0 0"/>
      <mass value="0.3"/>
      <inertia ixx="0.01" ixy="0.0" ixz="0.0" iyy="0.01" iyz="0.0" izz="0.01"/>
    </inertial>
  </link>
  <joint name="front_lidar_joint" type="fixed">
    <parent link="base_link"/>
    <child link="front_lidar_link"/>
    <origin rpy="0 0 0" xyz="0.38 0.25 0.15"/>
  </joint>
  <link name="back_lidar_link">
    <visual>
      <origin rpy="0 0 0" xyz="0 0 0"/>
      <geometry>
        <mesh filename="package://seer_description/meshes/lidar.stl" scale="0.1 0.1 0.1"/>
      </geometry>
      <material name="grey">
        <color rgba="0.5 0.5 0.5 1.0"/>
      </material>
    </visual>
    <collision>
      <origin rpy="0 0 0" xyz="0 0 0"/>
      <geometry>
        <cylinder length="0.08" radius="0.05"/>
      </geometry>
    </collision>
    <inertial>
      <origin rpy="0 0 0" xyz="0 0 0"/>
      <mass value="0.3"/>
      <inertia ixx="0.01" ixy="0.0" ixz="0.0" iyy="0.01" iyz="0.0" izz="0.01"/>
    </inertial>
  </link>
  <joint name="back_lidar_joint" type="fixed">
    <parent link="base_link"/>
    <child link="back_lidar_link"/>
    <origin rpy="0 0 0" xyz="-0.38 -0.25 0.15"/>
  </joint>
  <link name="front_caster">
    <collision>
      <origin rpy="0 0 0" xyz="0 0 0"/>
      <geometry>
        <sphere radius="0.095"/>
      </geometry>
    </collision>
    <inertial>
      <mass value="1.0"/>
      <inertia ixx="0.01" ixy="0" ixz="0" iyy="0.01" iyz="0" izz="0.01"/>
    </inertial>
  </link>
  <!-- <joint name="front_caster_joint" type="fixed">
    <parent link="base_link" />
    <child link="front_caster" />
    <origin xyz="0.3 0 ${wheel_zoff}" rpy="0 0 0" />
  </joint> -->
  <link name="rear_caster">
    <collision>
      <origin rpy="0 0 0" xyz="0 0 0"/>
      <geometry>
        <sphere radius="0.095"/>
      </geometry>
    </collision>
    <inertial>
      <mass value="1.0"/>
      <inertia ixx="0.01" ixy="0" ixz="0" iyy="0.01" iyz="0" izz="0.01"/>
    </inertial>
  </link>
  <!-- <joint name="rear_caster_joint" type="fixed">
    <parent link="base_link" />
    <child link="rear_caster" />
    <origin xyz="-0.3 0 ${wheel_zoff}" rpy="0 0 0" />
  </joint> -->
  <joint name="front_caster_joint" type="fixed">
    <parent link="base_link"/>
    <child link="front_caster"/>
    <origin rpy="0 0 0" xyz="0.3 0 0.095"/>
  </joint>
  <joint name="rear_caster_joint" type="fixed">
    <parent link="base_link"/>
    <child link="rear_caster"/>
    <origin rpy="0 0 0" xyz="-0.3 0 0.095"/>
  </joint>
  <!-- control simulation gazebo -->
  <gazebo reference="base_link">
    <material>Gazebo/White</material>
  </gazebo>
  <gazebo reference="left_wheel_link">
    <material>Gazebo/Black</material>
    <mu1>1.0</mu1>
    <mu2>1.0</mu2>
  </gazebo>
  <gazebo reference="right_wheel_link">
    <material>Gazebo/Black</material>
    <mu1>1.0</mu1>
    <mu2>1.0</mu2>
  </gazebo>
  <gazebo reference="front_caster">
    <mu1>0.0</mu1>
    <mu2>0.0</mu2>
    <material>Gazebo/Grey</material>
  </gazebo>
  <gazebo reference="rear_caster">
    <mu1>0.0</mu1>
    <mu2>0.0</mu2>
    <material>Gazebo/Grey</material>
  </gazebo>
  <gazebo>
    <plugin filename="gz-sim-diff-drive-system" name="gz::sim::systems::DiffDrive">
      <left_joint>left_wheel_joint</left_joint>
      <right_joint>right_wheel_joint</right_joint>
      <wheel_separation>0.6</wheel_separation>
      <wheel_radius>0.1</wheel_radius>
      <max_linear_acceleration>1.0</max_linear_acceleration>
      <max_angular_acceleration>1.0</max_angular_acceleration>
      <max_linear_velocity>1.5</max_linear_velocity>
      <max_angular_velocity>0.5</max_angular_velocity>
      <topic>cmd_vel</topic>
      <odom_topic>odom</odom_topic>
      <frame_id>odom</frame_id>
      <child_frame_id>base_footprint</child_frame_id>
      <odom_publisher_frequency>30</odom_publisher_frequency>
    </plugin>
    <plugin filename="gz-sim-joint-state-publisher-system" name="gz::sim::systems::JointStatePublisher">
      <topic>joint_states</topic>
      <joint_name>left_wheel_joint</joint_name>
      <joint_name>right_wheel_joint</joint_name>
    </plugin>
  </gazebo>
</robot>
